Workbook

Sheet Summary
A1: Transaction Monitoring Scenarios — Test Summary
A2: Figures are formulas over 'Test Cases' and update as Status is filled in. Thresholds are configurable defaults, not regulatory values.
A4: Category | B4: Scenarios | C4: Test Cases | D4: Positive | E4: Negative | F4: Boundary | G4: Edge | H4: Pass | I4: Fail | J4: Blocked | K4: Not Run | L4: Executed % | M4: Pass %
A5: Velocity & Frequency | B5: =COUNTIF('Scenario Catalogue'!$B$2:$B$121,A5) | C5: =COUNTIF('Test Cases'!$B$2:$B$315,A5) | D5: =COUNTIFS('Test Cases'!$B$2:$B$315,$A5,'Test Cases'!$E$2:$E$315,"Positive") | E5: =COUNTIFS('Test Cases'!$B$2:$B$315,$A5,'Test Cases'!$E$2:$E$315,"Negative") | F5: =COUNTIFS('Test Cases'!$B$2:$B$315,$A5,'Test Cases'!$E$2:$E$315,"Boundary") | G5: =COUNTIFS('Test Cases'!$B$2:$B$315,$A5,'Test Cases'!$E$2:$E$315,"Edge") | H5: =COUNTIFS('Test Cases'!$B$2:$B$315,$A5,'Test Cases'!$J$2:$J$315,"Pass") | I5: =COUNTIFS('Test Cases'!$B$2:$B$315,$A5,'Test Cases'!$J$2:$J$315,"Fail") | J5: =COUNTIFS('Test Cases'!$B$2:$B$315,$A5,'Test Cases'!$J$2:$J$315,"Blocked") | K5: =COUNTIFS('Test Cases'!$B$2:$B$315,$A5,'Test Cases'!$J$2:$J$315,"Not Run") | L5: =IF(C5=0,0,(C5-K5)/C5) | M5: =IF((H5+I5+J5)=0,0,H5/(H5+I5+J5))
A6: Amount & Thresholds | B6: =COUNTIF('Scenario Catalogue'!$B$2:$B$121,A6) | C6: =COUNTIF('Test Cases'!$B$2:$B$315,A6) | D6: =COUNTIFS('Test Cases'!$B$2:$B$315,$A6,'Test Cases'!$E$2:$E$315,"Positive") | E6: =COUNTIFS('Test Cases'!$B$2:$B$315,$A6,'Test Cases'!$E$2:$E$315,"Negative") | F6: =COUNTIFS('Test Cases'!$B$2:$B$315,$A6,'Test Cases'!$E$2:$E$315,"Boundary") | G6: =COUNTIFS('Test Cases'!$B$2:$B$315,$A6,'Test Cases'!$E$2:$E$315,"Edge") | H6: =COUNTIFS('Test Cases'!$B$2:$B$315,$A6,'Test Cases'!$J$2:$J$315,"Pass") | I6: =COUNTIFS('Test Cases'!$B$2:$B$315,$A6,'Test Cases'!$J$2:$J$315,"Fail") | J6: =COUNTIFS('Test Cases'!$B$2:$B$315,$A6,'Test Cases'!$J$2:$J$315,"Blocked") | K6: =COUNTIFS('Test Cases'!$B$2:$B$315,$A6,'Test Cases'!$J$2:$J$315,"Not Run") | L6: =IF(C6=0,0,(C6-K6)/C6) | M6: =IF((H6+I6+J6)=0,0,H6/(H6+I6+J6))
A7: Structuring & Smurfing | B7: =COUNTIF('Scenario Catalogue'!$B$2:$B$121,A7) | C7: =COUNTIF('Test Cases'!$B$2:$B$315,A7) | D7: =COUNTIFS('Test Cases'!$B$2:$B$315,$A7,'Test Cases'!$E$2:$E$315,"Positive") | E7: =COUNTIFS('Test Cases'!$B$2:$B$315,$A7,'Test Cases'!$E$2:$E$315,"Negative") | F7: =COUNTIFS('Test Cases'!$B$2:$B$315,$A7,'Test Cases'!$E$2:$E$315,"Boundary") | G7: =COUNTIFS('Test Cases'!$B$2:$B$315,$A7,'Test Cases'!$E$2:$E$315,"Edge") | H7: =COUNTIFS('Test Cases'!$B$2:$B$315,$A7,'Test Cases'!$J$2:$J$315,"Pass") | I7: =COUNTIFS('Test Cases'!$B$2:$B$315,$A7,'Test Cases'!$J$2:$J$315,"Fail") | J7: =COUNTIFS('Test Cases'!$B$2:$B$315,$A7,'Test Cases'!$J$2:$J$315,"Blocked") | K7: =COUNTIFS('Test Cases'!$B$2:$B$315,$A7,'Test Cases'!$J$2:$J$315,"Not Run") | L7: =IF(C7=0,0,(C7-K7)/C7) | M7: =IF((H7+I7+J7)=0,0,H7/(H7+I7+J7))
A8: Rapid Movement & Pass-through | B8: =COUNTIF('Scenario Catalogue'!$B$2:$B$121,A8) | C8: =COUNTIF('Test Cases'!$B$2:$B$315,A8) | D8: =COUNTIFS('Test Cases'!$B$2:$B$315,$A8,'Test Cases'!$E$2:$E$315,"Positive") | E8: =COUNTIFS('Test Cases'!$B$2:$B$315,$A8,'Test Cases'!$E$2:$E$315,"Negative") | F8: =COUNTIFS('Test Cases'!$B$2:$B$315,$A8,'Test Cases'!$E$2:$E$315,"Boundary") | G8: =COUNTIFS('Test Cases'!$B$2:$B$315,$A8,'Test Cases'!$E$2:$E$315,"Edge") | H8: =COUNTIFS('Test Cases'!$B$2:$B$315,$A8,'Test Cases'!$J$2:$J$315,"Pass") | I8: =COUNTIFS('Test Cases'!$B$2:$B$315,$A8,'Test Cases'!$J$2:$J$315,"Fail") | J8: =COUNTIFS('Test Cases'!$B$2:$B$315,$A8,'Test Cases'!$J$2:$J$315,"Blocked") | K8: =COUNTIFS('Test Cases'!$B$2:$B$315,$A8,'Test Cases'!$J$2:$J$315,"Not Run") | L8: =IF(C8=0,0,(C8-K8)/C8) | M8: =IF((H8+I8+J8)=0,0,H8/(H8+I8+J8))
A9: Fan-in / Fan-out | B9: =COUNTIF('Scenario Catalogue'!$B$2:$B$121,A9) | C9: =COUNTIF('Test Cases'!$B$2:$B$315,A9) | D9: =COUNTIFS('Test Cases'!$B$2:$B$315,$A9,'Test Cases'!$E$2:$E$315,"Positive") | E9: =COUNTIFS('Test Cases'!$B$2:$B$315,$A9,'Test Cases'!$E$2:$E$315,"Negative") | F9: =COUNTIFS('Test Cases'!$B$2:$B$315,$A9,'Test Cases'!$E$2:$E$315,"Boundary") | G9: =COUNTIFS('Test Cases'!$B$2:$B$315,$A9,'Test Cases'!$E$2:$E$315,"Edge") | H9: =COUNTIFS('Test Cases'!$B$2:$B$315,$A9,'Test Cases'!$J$2:$J$315,"Pass") | I9: =COUNTIFS('Test Cases'!$B$2:$B$315,$A9,'Test Cases'!$J$2:$J$315,"Fail") | J9: =COUNTIFS('Test Cases'!$B$2:$B$315,$A9,'Test Cases'!$J$2:$J$315,"Blocked") | K9: =COUNTIFS('Test Cases'!$B$2:$B$315,$A9,'Test Cases'!$J$2:$J$315,"Not Run") | L9: =IF(C9=0,0,(C9-K9)/C9) | M9: =IF((H9+I9+J9)=0,0,H9/(H9+I9+J9))
A10: Geographic & Impossible Travel | B10: =COUNTIF('Scenario Catalogue'!$B$2:$B$121,A10) | C10: =COUNTIF('Test Cases'!$B$2:$B$315,A10) | D10: =COUNTIFS('Test Cases'!$B$2:$B$315,$A10,'Test Cases'!$E$2:$E$315,"Positive") | E10: =COUNTIFS('Test Cases'!$B$2:$B$315,$A10,'Test Cases'!$E$2:$E$315,"Negative") | F10: =COUNTIFS('Test Cases'!$B$2:$B$315,$A10,'Test Cases'!$E$2:$E$315,"Boundary") | G10: =COUNTIFS('Test Cases'!$B$2:$B$315,$A10,'Test Cases'!$E$2:$E$315,"Edge") | H10: =COUNTIFS('Test Cases'!$B$2:$B$315,$A10,'Test Cases'!$J$2:$J$315,"Pass") | I10: =COUNTIFS('Test Cases'!$B$2:$B$315,$A10,'Test Cases'!$J$2:$J$315,"Fail") | J10: =COUNTIFS('Test Cases'!$B$2:$B$315,$A10,'Test Cases'!$J$2:$J$315,"Blocked") | K10: =COUNTIFS('Test Cases'!$B$2:$B$315,$A10,'Test Cases'!$J$2:$J$315,"Not Run") | L10: =IF(C10=0,0,(C10-K10)/C10) | M10: =IF((H10+I10+J10)=0,0,H10/(H10+I10+J10))
A11: Device, IP & Channel | B11: =COUNTIF('Scenario Catalogue'!$B$2:$B$121,A11) | C11: =COUNTIF('Test Cases'!$B$2:$B$315,A11) | D11: =COUNTIFS('Test Cases'!$B$2:$B$315,$A11,'Test Cases'!$E$2:$E$315,"Positive") | E11: =COUNTIFS('Test Cases'!$B$2:$B$315,$A11,'Test Cases'!$E$2:$E$315,"Negative") | F11: =COUNTIFS('Test Cases'!$B$2:$B$315,$A11,'Test Cases'!$E$2:$E$315,"Boundary") | G11: =COUNTIFS('Test Cases'!$B$2:$B$315,$A11,'Test Cases'!$E$2:$E$315,"Edge") | H11: =COUNTIFS('Test Cases'!$B$2:$B$315,$A11,'Test Cases'!$J$2:$J$315,"Pass") | I11: =COUNTIFS('Test Cases'!$B$2:$B$315,$A11,'Test Cases'!$J$2:$J$315,"Fail") | J11: =COUNTIFS('Test Cases'!$B$2:$B$315,$A11,'Test Cases'!$J$2:$J$315,"Blocked") | K11: =COUNTIFS('Test Cases'!$B$2:$B$315,$A11,'Test Cases'!$J$2:$J$315,"Not Run") | L11: =IF(C11=0,0,(C11-K11)/C11) | M11: =IF((H11+I11+J11)=0,0,H11/(H11+I11+J11))
A12: Behavioural Change & Profile Mismatch | B12: =COUNTIF('Scenario Catalogue'!$B$2:$B$121,A12) | C12: =COUNTIF('Test Cases'!$B$2:$B$315,A12) | D12: =COUNTIFS('Test Cases'!$B$2:$B$315,$A12,'Test Cases'!$E$2:$E$315,"Positive") | E12: =COUNTIFS('Test Cases'!$B$2:$B$315,$A12,'Test Cases'!$E$2:$E$315,"Negative") | F12: =COUNTIFS('Test Cases'!$B$2:$B$315,$A12,'Test Cases'!$E$2:$E$315,"Boundary") | G12: =COUNTIFS('Test Cases'!$B$2:$B$315,$A12,'Test Cases'!$E$2:$E$315,"Edge") | H12: =COUNTIFS('Test Cases'!$B$2:$B$315,$A12,'Test Cases'!$J$2:$J$315,"Pass") | I12: =COUNTIFS('Test Cases'!$B$2:$B$315,$A12,'Test Cases'!$J$2:$J$315,"Fail") | J12: =COUNTIFS('Test Cases'!$B$2:$B$315,$A12,'Test Cases'!$J$2:$J$315,"Blocked") | K12: =COUNTIFS('Test Cases'!$B$2:$B$315,$A12,'Test Cases'!$J$2:$J$315,"Not Run") | L12: =IF(C12=0,0,(C12-K12)/C12) | M12: =IF((H12+I12+J12)=0,0,H12/(H12+I12+J12))
A13: Cash-in / Cash-out | B13: =COUNTIF('Scenario Catalogue'!$B$2:$B$121,A13) | C13: =COUNTIF('Test Cases'!$B$2:$B$315,A13) | D13: =COUNTIFS('Test Cases'!$B$2:$B$315,$A13,'Test Cases'!$E$2:$E$315,"Positive") | E13: =COUNTIFS('Test Cases'!$B$2:$B$315,$A13,'Test Cases'!$E$2:$E$315,"Negative") | F13: =COUNTIFS('Test Cases'!$B$2:$B$315,$A13,'Test Cases'!$E$2:$E$315,"Boundary") | G13: =COUNTIFS('Test Cases'!$B$2:$B$315,$A13,'Test Cases'!$E$2:$E$315,"Edge") | H13: =COUNTIFS('Test Cases'!$B$2:$B$315,$A13,'Test Cases'!$J$2:$J$315,"Pass") | I13: =COUNTIFS('Test Cases'!$B$2:$B$315,$A13,'Test Cases'!$J$2:$J$315,"Fail") | J13: =COUNTIFS('Test Cases'!$B$2:$B$315,$A13,'Test Cases'!$J$2:$J$315,"Blocked") | K13: =COUNTIFS('Test Cases'!$B$2:$B$315,$A13,'Test Cases'!$J$2:$J$315,"Not Run") | L13: =IF(C13=0,0,(C13-K13)/C13) | M13: =IF((H13+I13+J13)=0,0,H13/(H13+I13+J13))
A14: Agent Network | B14: =COUNTIF('Scenario Catalogue'!$B$2:$B$121,A14) | C14: =COUNTIF('Test Cases'!$B$2:$B$315,A14) | D14: =COUNTIFS('Test Cases'!$B$2:$B$315,$A14,'Test Cases'!$E$2:$E$315,"Positive") | E14: =COUNTIFS('Test Cases'!$B$2:$B$315,$A14,'Test Cases'!$E$2:$E$315,"Negative") | F14: =COUNTIFS('Test Cases'!$B$2:$B$315,$A14,'Test Cases'!$E$2:$E$315,"Boundary") | G14: =COUNTIFS('Test Cases'!$B$2:$B$315,$A14,'Test Cases'!$E$2:$E$315,"Edge") | H14: =COUNTIFS('Test Cases'!$B$2:$B$315,$A14,'Test Cases'!$J$2:$J$315,"Pass") | I14: =COUNTIFS('Test Cases'!$B$2:$B$315,$A14,'Test Cases'!$J$2:$J$315,"Fail") | J14: =COUNTIFS('Test Cases'!$B$2:$B$315,$A14,'Test Cases'!$J$2:$J$315,"Blocked") | K14: =COUNTIFS('Test Cases'!$B$2:$B$315,$A14,'Test Cases'!$J$2:$J$315,"Not Run") | L14: =IF(C14=0,0,(C14-K14)/C14) | M14: =IF((H14+I14+J14)=0,0,H14/(H14+I14+J14))
A15: Merchant | B15: =COUNTIF('Scenario Catalogue'!$B$2:$B$121,A15) | C15: =COUNTIF('Test Cases'!$B$2:$B$315,A15) | D15: =COUNTIFS('Test Cases'!$B$2:$B$315,$A15,'Test Cases'!$E$2:$E$315,"Positive") | E15: =COUNTIFS('Test Cases'!$B$2:$B$315,$A15,'Test Cases'!$E$2:$E$315,"Negative") | F15: =COUNTIFS('Test Cases'!$B$2:$B$315,$A15,'Test Cases'!$E$2:$E$315,"Boundary") | G15: =COUNTIFS('Test Cases'!$B$2:$B$315,$A15,'Test Cases'!$E$2:$E$315,"Edge") | H15: =COUNTIFS('Test Cases'!$B$2:$B$315,$A15,'Test Cases'!$J$2:$J$315,"Pass") | I15: =COUNTIFS('Test Cases'!$B$2:$B$315,$A15,'Test Cases'!$J$2:$J$315,"Fail") | J15: =COUNTIFS('Test Cases'!$B$2:$B$315,$A15,'Test Cases'!$J$2:$J$315,"Blocked") | K15: =COUNTIFS('Test Cases'!$B$2:$B$315,$A15,'Test Cases'!$J$2:$J$315,"Not Run") | L15: =IF(C15=0,0,(C15-K15)/C15) | M15: =IF((H15+I15+J15)=0,0,H15/(H15+I15+J15))
A16: Reversals, Refunds & Failed Attempts | B16: =COUNTIF('Scenario Catalogue'!$B$2:$B$121,A16) | C16: =COUNTIF('Test Cases'!$B$2:$B$315,A16) | D16: =COUNTIFS('Test Cases'!$B$2:$B$315,$A16,'Test Cases'!$E$2:$E$315,"Positive") | E16: =COUNTIFS('Test Cases'!$B$2:$B$315,$A16,'Test Cases'!$E$2:$E$315,"Negative") | F16: =COUNTIFS('Test Cases'!$B$2:$B$315,$A16,'Test Cases'!$E$2:$E$315,"Boundary") | G16: =COUNTIFS('Test Cases'!$B$2:$B$315,$A16,'Test Cases'!$E$2:$E$315,"Edge") | H16: =COUNTIFS('Test Cases'!$B$2:$B$315,$A16,'Test Cases'!$J$2:$J$315,"Pass") | I16: =COUNTIFS('Test Cases'!$B$2:$B$315,$A16,'Test Cases'!$J$2:$J$315,"Fail") | J16: =COUNTIFS('Test Cases'!$B$2:$B$315,$A16,'Test Cases'!$J$2:$J$315,"Blocked") | K16: =COUNTIFS('Test Cases'!$B$2:$B$315,$A16,'Test Cases'!$J$2:$J$315,"Not Run") | L16: =IF(C16=0,0,(C16-K16)/C16) | M16: =IF((H16+I16+J16)=0,0,H16/(H16+I16+J16))
... A25: Engine Edge Cases (applies to all scenarios) | B25: =COUNTIF('Scenario Catalogue'!$B$2:$B$121,A25) | C25: =COUNTIF('Test Cases'!$B$2:$B$315,A25) | D25: =COUNTIFS('Test Cases'!$B$2:$B$315,$A25,'Test Cases'!$E$2:$E$315,"Positive") | E25: =COUNTIFS('Test Cases'!$B$2:$B$315,$A25,'Test Cases'!$E$2:$E$315,"Negative") | F25: =COUNTIFS('Test Cases'!$B$2:$B$315,$A25,'Test Cases'!$E$2:$E$315,"Boundary") | G25: =COUNTIFS('Test Cases'!$B$2:$B$315,$A25,'Test Cases'!$E$2:$E$315,"Edge") | H25: =COUNTIFS('Test Cases'!$B$2:$B$315,$A25,'Test Cases'!$J$2:$J$315,"Pass") | I25: =COUNTIFS('Test Cases'!$B$2:$B$315,$A25,'Test Cases'!$J$2:$J$315,"Fail") | J25: =COUNTIFS('Test Cases'!$B$2:$B$315,$A25,'Test Cases'!$J$2:$J$315,"Blocked") | K25: =COUNTIFS('Test Cases'!$B$2:$B$315,$A25,'Test Cases'!$J$2:$J$315,"Not Run") | L25: =IF(C25=0,0,(C25-K25)/C25) | M25: =IF((H25+I25+J25)=0,0,H25/(H25+I25+J25))
A26: Total | B26: =SUM(B5:B25) | C26: =SUM(C5:C25) | D26: =SUM(D5:D25) | E26: =SUM(E5:E25) | F26: =SUM(F5:F25) | G26: =SUM(G5:G25) | H26: =SUM(H5:H25) | I26: =SUM(I5:I25) | ... K26: =SUM(K5:K25) | L26: =IF(C26=0,0,(C26-K26)/C26) | M26: =IF((H26+I26+J26)=0,0,H26/(H26+I26+J26))

Sheet Scenario Catalogue
A1: Scenario ID | B1: Category | C1: Scenario | D1: Detection Logic | E1: Default Parameters (configurable) | F1: Alert Severity | G1: Priority | H1: # Test Cases
A2: VEL-01 | B2: Velocity & Frequency | C2: High count of cash withdrawals per day | D2: Count of completed cash-out/withdrawal transactions by the same customer within one calendar day (local time) ≥ N | E2: N=20 per day; channels=Agent, ATM; statuses counted=Completed | F2: High | G2: P1 | H2: =COUNTIF('Test Cases'!$C$2:$C$315,A2)
A3: VEL-02 | B3: Velocity & Frequency | C3: High count of withdrawals per hour (burst) | D3: Count of withdrawals within a rolling 60-minute window ≥ N | E3: N=8 per rolling hour | F3: High | G3: P1 | H3: =COUNTIF('Test Cases'!$C$2:$C$315,A3)
A4: VEL-03 | B4: Velocity & Frequency | C4: High count of outgoing P2P transfers per day | D4: Count of outgoing wallet-to-wallet transfers per customer per day ≥ N | E4: N=30 per day | F4: Medium | G4: P1 | H4: =COUNTIF('Test Cases'!$C$2:$C$315,A4)
A5: VEL-04 | B5: Velocity & Frequency | C5: High count of incoming transfers per day | D5: Count of incoming transfers to one customer per day ≥ N | E5: N=25 per day | F5: Medium | G5: P1 | H5: =COUNTIF('Test Cases'!$C$2:$C$315,A5)
A6: VEL-05 | B6: Velocity & Frequency | C6: Weekly transaction count spike | D6: Count of all financial transactions in a rolling 7 days ≥ N | E6: N=100 per 7 days (individual) | F6: Medium | G6: P2 | H6: =COUNTIF('Test Cases'!$C$2:$C$315,A6)
A7: VEL-06 | B7: Velocity & Frequency | C7: Many transactions within minutes of account opening | D7: Count of transactions within X hours after registration ≥ N | E7: X=24 hours; N=10 | F7: High | G7: P1 | H7: =COUNTIF('Test Cases'!$C$2:$C$315,A7)
A8: VEL-07 | B8: Velocity & Frequency | C8: Transactions at regular fixed intervals (automation) | D8: ≥ N transactions with near-identical time gaps (std-dev of gaps ≤ T seconds) | E8: N=10; T=5 seconds | F8: Medium | G8: P2 | H8: =COUNTIF('Test Cases'!$C$2:$C$315,A8)
A9: VEL-08 | B9: Velocity & Frequency | C9: High count of distinct channels in a day | D9: Number of distinct channels used (App, Agent, ATM, USSD, Web) in one day ≥ N with total amount ≥ A | E9: N=4; A=1,000 | F9: Low | G9: P3 | H9: =COUNTIF('Test Cases'!$C$2:$C$315,A9)
A10: AMT-01 | B10: Amount & Thresholds | C10: Single large transaction | D10: Single transaction amount ≥ threshold for customer type | E10: Individual 10,000; Corporate 50,000 (base currency) | F10: Medium | G10: P1 | H10: =COUNTIF('Test Cases'!$C$2:$C$315,A10)
A11: AMT-02 | B11: Amount & Thresholds | C11: Daily cumulative amount | D11: Sum of outgoing amounts per customer per calendar day ≥ A | E11: A=5,000 (individual) | F11: Medium | G11: P1 | H11: =COUNTIF('Test Cases'!$C$2:$C$315,A11)
A12: AMT-03 | B12: Amount & Thresholds | C12: Monthly cumulative amount vs declared income | D12: Monthly incoming amount > K × declared monthly income | E12: K=3 | F12: High | G12: P1 | H12: =COUNTIF('Test Cases'!$C$2:$C$315,A12)
A13: AMT-04 | B13: Amount & Thresholds | C13: Transaction amount vs expected activity in KYC | D13: Monthly volume exceeds expected monthly activity declared at onboarding by P% | E13: P=200% | F13: Medium | G13: P1 | H13: =COUNTIF('Test Cases'!$C$2:$C$315,A13)
... A121: ENG-12 | B121: Engine Edge Cases (applies to all scenarios) | C121: Performance at scale | D121: Windowed rules run on peak daily volume within target time | E121: Volume and target per NFR | F121: — | G121: P1 | H121: =COUNTIF('Test Cases'!$C$2:$C$315,A121)

Sheet Test Cases
A1: TC ID | B1: Category | C1: Scenario ID | D1: Scenario | E1: Test Type | F1: Test Description & Transaction Data | G1: Expected Result | H1: Alert Severity | I1: Priority | J1: Status | K1: Actual Result | L1: Tester | M1: Execution Date | N1: Defect ID | O1: Notes
A2: TM-VEL-01-01 | B2: Velocity & Frequency | C2: VEL-01 | D2: High count of cash withdrawals per day | E2: Positive | F2: C1 performs 20 cash withdrawals of 50 JOD at agents between 09:00 and 18:00 on the same day | G2: Alert raised on the 20th withdrawal; evidence lists all 20 transactions and the day window | H2: High | I2: P1 | J2: Pass | K2: 1 alert (ALR-202610-000146) triggered by the 20th withdrawal (V01A-369-19); 20 contributing transactions linked; evidence window 2025-01-03 21:00Z–2025-01-04 21:00Z. | L2: Claude (automated test suite) | M2: 2026-10-15 | O2: Automated: VelocityTests.VEL_01_cash_withdrawals_per_day
A3: TM-VEL-01-02 | B3: Velocity & Frequency | C3: VEL-01 | D3: High count of cash withdrawals per day | E3: Boundary | F3: C1 performs exactly 19 withdrawals in one day | G3: No alert | H3: High | I3: P1 | J3: Pass | K3: 19 withdrawals → 0 alerts. | L3: Claude (automated test suite) | M3: 2026-10-15 | O3: Automated: VelocityTests.VEL_01_cash_withdrawals_per_day
A4: TM-VEL-01-03 | B4: Velocity & Frequency | C4: VEL-01 | D4: High count of cash withdrawals per day | E4: Boundary | F4: 20 withdrawals where the 20th is at 23:59:59 local time | G4: Alert raised (same calendar day) | H4: High | I4: P1 | J4: Pass | K4: 20th withdrawal at 23:59:59 local → 1 alert (same calendar day 2025-01-03 21:00Z–2025-01-04 21:00Z). | L4: Claude (automated test suite) | M4: 2026-10-15 | O4: Automated: VelocityTests.VEL_01_cash_withdrawals_per_day
A5: TM-VEL-01-04 | B5: Velocity & Frequency | C5: VEL-01 | D5: High count of cash withdrawals per day | E5: Negative | F5: 10 withdrawals at 23:00–23:59 and 10 at 00:00–01:00 next day (local) | G5: No alert for daily calendar rule (two days of 10) | H5: High | I5: P1 | J5: Pass | K5: 10 withdrawals 23:00–23:45 and 10 on the next local day → 0 alerts (two calendar days of 10). | L5: Claude (automated test suite) | M5: 2026-10-15 | O5: Automated: VelocityTests.VEL_01_cash_withdrawals_per_day
A6: TM-VEL-01-05 | B6: Velocity & Frequency | C6: VEL-01 | D6: High count of cash withdrawals per day | E6: Negative | F6: 20 withdrawal attempts where 6 are Failed | G6: No alert (only 14 completed) | H6: High | I6: P1 | J6: Pass | K6: 20 attempts, 6 Failed → 14 completed counted → 0 alerts. | L6: Claude (automated test suite) | M6: 2026-10-15 | O6: Automated: VelocityTests.VEL_01_cash_withdrawals_per_day
A7: TM-VEL-01-06 | B7: Velocity & Frequency | C7: VEL-01 | D7: High count of cash withdrawals per day | E7: Edge | F7: 20 withdrawals, 3 later reversed | G7: Behaviour per configured netting policy; evidence shows reversals | H7: High | I7: P1 | J7: Pass | K7: Rule netting policy 'Exclude': 3 of 20 withdrawals reversed → 17 counted → 0 alerts (with policy 'Include' the reversed items would count). | L7: Claude (automated test suite) | M7: 2026-10-15 | O7: Automated: VelocityTests.VEL_01_cash_withdrawals_per_day
A8: TM-VEL-01-07 | B8: Velocity & Frequency | C8: VEL-01 | D8: High count of cash withdrawals per day | E8: Edge | F8: 20 withdrawals split across 2 wallets of the same customer | G8: Alert raised at customer level (aggregation by resolved customer) | H8: High | I8: P1 | J8: Pass | K8: 20 withdrawals split 10/10 across two wallets of the same customer → 1 customer-level alert. | L8: Claude (automated test suite) | M8: 2026-10-15 | O8: Automated: VelocityTests.VEL_01_cash_withdrawals_per_day
A9: TM-VEL-02-01 | B9: Velocity & Frequency | C9: VEL-02 | D9: High count of withdrawals per hour (burst) | E9: Positive | F9: C2 performs 8 ATM withdrawals of 100 JOD between 14:00 and 14:45 | G9: Alert raised; window boundaries in evidence | H9: High | I9: P1 | J9: Pass | K9: 8 ATM withdrawals 14:00–14:42 → 1 alert; rolling 60-min window boundaries in evidence. | L9: Claude (automated test suite) | M9: 2026-10-15 | O9: Automated: VelocityTests.VEL_02_withdrawal_burst_per_hour
A10: TM-VEL-02-02 | B10: Velocity & Frequency | C10: VEL-02 | D10: High count of withdrawals per hour (burst) | E10: Boundary | F10: 8 withdrawals spanning exactly 60 minutes 01 second | G10: No alert | H10: High | I10: P1 | J10: Pass | K10: 8 withdrawals spanning 60 min 01 s (window (t−60m, t]) → 0 alerts. | L10: Claude (automated test suite) | M10: 2026-10-15 | O10: Automated: VelocityTests.VEL_02_withdrawal_burst_per_hour
A11: TM-VEL-02-03 | B11: Velocity & Frequency | C11: VEL-02 | D11: High count of withdrawals per hour (burst) | E11: Negative | F11: 8 withdrawals spread evenly across 8 hours | G11: No alert for burst rule | H11: High | I11: P1 | J11: Pass | K11: 8 withdrawals one per hour → 0 alerts. | L11: Claude (automated test suite) | M11: 2026-10-15 | O11: Automated: VelocityTests.VEL_02_withdrawal_burst_per_hour
A12: TM-VEL-02-04 | B12: Velocity & Frequency | C12: VEL-02 | D12: High count of withdrawals per hour (burst) | E12: Edge | F12: Burst window crosses midnight (23:30–00:20) | G12: Alert raised (rolling window ignores calendar day) | H12: High | I12: P1 | J12: Pass | K12: Burst 23:30–00:19 local across midnight → 1 alert (rolling window ignores calendar day). | L12: Claude (automated test suite) | M12: 2026-10-15 | O12: Automated: VelocityTests.VEL_02_withdrawal_burst_per_hour
A13: TM-VEL-03-01 | B13: Velocity & Frequency | C13: VEL-03 | D13: High count of outgoing P2P transfers per day | E13: Positive | F13: C3 sends 30 P2P transfers of 10–40 JOD to various wallets in one day | G13: Alert raised | H13: Medium | I13: P1 | J13: Pass | K13: 30 P2P transfers (10–40 JOD) in one day → 1 alert. | L13: Claude (automated test suite) | M13: 2026-10-15 | O13: Automated: VelocityTests.VEL_03_outgoing_p2p_per_day
A14: TM-VEL-03-02 | B14: Velocity & Frequency | C14: VEL-03 | D14: High count of outgoing P2P transfers per day | E14: Boundary | F14: 29 transfers | G14: No alert | H14: Medium | I14: P1 | J14: Pass | K14: 29 transfers → 0 alerts. | L14: Claude (automated test suite) | M14: 2026-10-15 | O14: Automated: VelocityTests.VEL_03_outgoing_p2p_per_day
A15: TM-VEL-03-03 | B15: Velocity & Frequency | C15: VEL-03 | D15: High count of outgoing P2P transfers per day | E15: Negative | F15: 30 transfers where 15 are to the customer's own second wallet | G15: Own-account transfers excluded per configuration; no alert | H15: Medium | I15: P1 | J15: Pass | K15: 30 transfers of which 15 to the customer's own second wallet → 0 alert(s). Own-account transfers excluded by the rule filter txn.isOwnAccount = false (15 counted). | L15: Claude (automated test suite) | M15: 2026-10-15 | N15: DEF-TM-01 (fixed) | O15: Automated: VelocityTests.VEL_03_outgoing_p2p_per_day. Failed in the first execution (DEF-TM-01: Own-wallet / self-transfer exclusion not configurable); fixed: Rule field txn.isOwnAccount; re-tested 2026-10-15.
A16: TM-VEL-03-04 | B16: Velocity & Frequency | C16: VEL-03 | D16: High count of outgoing P2P transfers per day | E16: Edge | F16: Customer type = Merchant with higher configured threshold (N=200) | G16: No alert at 30 | H16: Medium | I16: P1 | J16: Pass | K16: Merchant with 30 transfers: individual rule scoped out, merchant rule threshold 200 → 0 alerts. | L16: Claude (automated test suite) | M16: 2026-10-15 | O16: Automated: VelocityTests.VEL_03_outgoing_p2p_per_day
A17: TM-VEL-04-01 | B17: Velocity & Frequency | C17: VEL-04 | D17: High count of incoming transfers per day | E17: Positive | F17: C4 receives 25 transfers of 20 JOD from different senders in one day | G17: Alert raised | H17: Medium | I17: P1 | J17: Pass | K17: 25 incoming transfers of 20 from different senders → 1 alert. | L17: Claude (automated test suite) | M17: 2026-10-15 | O17: Automated: VelocityTests.VEL_04_incoming_per_day
A18: TM-VEL-04-02 | B18: Velocity & Frequency | C18: VEL-04 | D18: High count of incoming transfers per day | E18: Boundary | F18: 24 incoming transfers | G18: No alert | H18: Medium | I18: P1 | J18: Pass | K18: 24 incoming → 0 alerts. | L18: Claude (automated test suite) | M18: 2026-10-15 | O18: Automated: VelocityTests.VEL_04_incoming_per_day
A19: TM-VEL-04-03 | B19: Velocity & Frequency | C19: VEL-04 | D19: High count of incoming transfers per day | E19: Negative | F19: 25 incoming refunds from a merchant | G19: Refunds excluded per configuration; no alert | H19: Medium | I19: P1 | J19: Pass | K19: 25 incoming merchant refunds excluded by type filter → 0 alerts. | L19: Claude (automated test suite) | M19: 2026-10-15 | O19: Automated: VelocityTests.VEL_04_incoming_per_day
A20: TM-VEL-04-04 | B20: Velocity & Frequency | C20: VEL-04 | D20: High count of incoming transfers per day | E20: Edge | F20: Incoming salary bulk payment counted as one batch | G20: Counted once; no alert | H20: Medium | I20: P1 | J20: Pass | K20: Salary bulk payment ingested as one batch record → counted once → 0 alerts. | L20: Claude (automated test suite) | M20: 2026-10-15 | O20: Automated: VelocityTests.VEL_04_incoming_per_day
A21: TM-VEL-05-01 | B21: Velocity & Frequency | C21: VEL-05 | D21: Weekly transaction count spike | E21: Positive | F21: C5 performs 101 transactions of mixed types in 6 days | G21: Alert raised | H21: Medium | I21: P2 | J21: Pass | K21: 101 mixed transactions in ~5.6 days → 1 alert(s). | L21: Claude (automated test suite) | M21: 2026-10-15 | O21: Automated: VelocityTests.VEL_05_weekly_count
A22: TM-VEL-05-02 | B22: Velocity & Frequency | C22: VEL-05 | D22: Weekly transaction count spike | E22: Boundary | F22: 100 transactions in 7 days | G22: Alert raised (≥) | H22: Medium | I22: P2 | J22: Pass | K22: Exactly 100 transactions within 6.9 days → 1 alert (≥). | L22: Claude (automated test suite) | M22: 2026-10-15 | O22: Automated: VelocityTests.VEL_05_weekly_count
A23: TM-VEL-05-03 | B23: Velocity & Frequency | C23: VEL-05 | D23: Weekly transaction count spike | E23: Negative | F23: 100 transactions over 8 days | G23: No alert | H23: Medium | I23: P2 | J23: Pass | K23: 100 transactions spread over 8 days → 0 alerts. | L23: Claude (automated test suite) | M23: 2026-10-15 | O23: Automated: VelocityTests.VEL_05_weekly_count
A24: TM-VEL-05-04 | B24: Velocity & Frequency | C24: VEL-05 | D24: Weekly transaction count spike | E24: Edge | F24: Rule applicability excludes corporate customers; corporate with 150 | G24: No alert | H24: Medium | I24: P2 | J24: Pass | K24: Corporate with 150 in a week, rule scoped to individuals → 0 alerts. | L24: Claude (automated test suite) | M24: 2026-10-15 | O24: Automated: VelocityTests.VEL_05_weekly_count
A25: TM-VEL-06-01 | B25: Velocity & Frequency | C25: VEL-06 | D25: Many transactions within minutes of account opening | E25: Positive | F25: New wallet registered 10:00; 10 transactions by 18:00 same day | G25: Alert raised; account age in evidence | H25: High | I25: P1 | J25: Pass | K25: Wallet registered on the day, 10 transactions 10:30–17:15 → 1 alert; account age (customer.accountAgeDays = 0) in the matched conditions. | L25: Claude (automated test suite) | M25: 2026-10-15 | O25: Automated: ExtendedCapabilityTests.VEL_06_activity_right_after_registration. Blocked in the first execution (capability gap); executable after the rule DSL extension.
A26: TM-VEL-06-02 | B26: Velocity & Frequency | C26: VEL-06 | D26: Many transactions within minutes of account opening | E26: Boundary | F26: 10th transaction at 24h 01m after registration | G26: No alert | H26: High | I26: P1 | J26: Pass | K26: 9 transactions from 10:00 and the 10th at 24 h 01 m → 0 alerts (rolling 24 h window). | L26: Claude (automated test suite) | M26: 2026-10-15 | O26: Automated: ExtendedCapabilityTests.VEL_06_activity_right_after_registration. Note: registration is stored as a date, so account age has day (not minute) precision.. Blocked in the first execution (capability gap); executable after the rule DSL extension.
A27: TM-VEL-06-03 | B27: Velocity & Frequency | C27: VEL-06 | D27: Many transactions within minutes of account opening | E27: Negative | F27: Existing 2-year-old customer does 10 transactions in a day | G27: Rule not applicable; no alert | H27: High | I27: P1 | J27: Pass | K27: Two-year-old customer with 10 transactions in a day → 0 alerts. | L27: Claude (automated test suite) | M27: 2026-10-15 | O27: Automated: ExtendedCapabilityTests.VEL_06_activity_right_after_registration. Blocked in the first execution (capability gap); executable after the rule DSL extension.
A28: TM-VEL-06-04 | B28: Velocity & Frequency | C28: VEL-06 | D28: Many transactions within minutes of account opening | E28: Edge | F28: Registration timestamp missing | G28: Data-quality issue raised; rule records unable-to-evaluate, not silent pass | H28: High | I28: P1 | J28: Pass | K28: Registration date missing → no silent pass: condition not met and data-quality item "[R_9215E93CF89D/customer.accountAgeDays] Rule R_9215E93CF89D v1 could not evaluate 'customer.accountAgeDays' for customer 105: value missing; condition treated as not met (result incomplete). Complete the customer data.". | L28: Claude (automated test suite) | M28: 2026-10-15 | O28: Automated: ExtendedCapabilityTests.VEL_06_activity_right_after_registration. Blocked in the first execution (capability gap); executable after the rule DSL extension.
A29: TM-VEL-07-01 | B29: Velocity & Frequency | C29: VEL-07 | D29: Transactions at regular fixed intervals (automation) | E29: Positive | F29: 12 transfers exactly every 60 seconds (±2s) | G29: Alert raised as possible scripted activity | H29: Medium | I29: P2 | J29: Blocked | K29: Capability gap — No aggregate for regularity of time gaps (standard deviation of inter-transaction intervals). Closest rule definition rejected by the rule validator: $.condition.aggregate: Unknown aggregate 'intervalStdDev'. Allowed: count, sum, distinctCounterparties, ratio, rapidMovement, dormancyDays, profileRatio, peerRatio, newCustomers, customersPerDevice, cycle, newCountries, historyCount, historySum, historyRatio, distinctCount, reciprocalCount, consecutiveDays, newCounterpartyShare, sharedDeviceSenders, typeShareChange, minutesSinceEvent.. | L29: Claude (automated test suite) | M29: 2026-10-15 | N29: GAP-VEL-07 | O29: Automated: CapabilityGapTests.Scenario_not_configurable (rule validator evidence)
A30: TM-VEL-07-02 | B30: Velocity & Frequency | C30: VEL-07 | D30: Transactions at regular fixed intervals (automation) | E30: Negative | F30: 12 transfers at random intervals | G30: No alert | H30: Medium | I30: P2 | J30: Blocked | K30: Capability gap — No aggregate for regularity of time gaps (standard deviation of inter-transaction intervals). Closest rule definition rejected by the rule validator: $.condition.aggregate: Unknown aggregate 'intervalStdDev'. Allowed: count, sum, distinctCounterparties, ratio, rapidMovement, dormancyDays, profileRatio, peerRatio, newCustomers, customersPerDevice, cycle, newCountries, historyCount, historySum, historyRatio, distinctCount, reciprocalCount, consecutiveDays, newCounterpartyShare, sharedDeviceSenders, typeShareChange, minutesSinceEvent.. | L30: Claude (automated test suite) | M30: 2026-10-15 | N30: GAP-VEL-07 | O30: Automated: CapabilityGapTests.Scenario_not_configurable (rule validator evidence)
A31: TM-VEL-07-03 | B31: Velocity & Frequency | C31: VEL-07 | D31: Transactions at regular fixed intervals (automation) | E31: Boundary | F31: 9 regular transfers | G31: No alert | H31: Medium | I31: P2 | J31: Blocked | K31: Capability gap — No aggregate for regularity of time gaps (standard deviation of inter-transaction intervals). Closest rule definition rejected by the rule validator: $.condition.aggregate: Unknown aggregate 'intervalStdDev'. Allowed: count, sum, distinctCounterparties, ratio, rapidMovement, dormancyDays, profileRatio, peerRatio, newCustomers, customersPerDevice, cycle, newCountries, historyCount, historySum, historyRatio, distinctCount, reciprocalCount, consecutiveDays, newCounterpartyShare, sharedDeviceSenders, typeShareChange, minutesSinceEvent.. | L31: Claude (automated test suite) | M31: 2026-10-15 | N31: GAP-VEL-07 | O31: Automated: CapabilityGapTests.Scenario_not_configurable (rule validator evidence)
A32: TM-VEL-07-04 | B32: Velocity & Frequency | C32: VEL-07 | D32: Transactions at regular fixed intervals (automation) | E32: Edge | F32: Scheduled standing order configured by customer | G32: Excluded by transaction sub-type; no alert | H32: Medium | I32: P2 | J32: Blocked | K32: Capability gap — No aggregate for regularity of time gaps (standard deviation of inter-transaction intervals). Closest rule definition rejected by the rule validator: $.condition.aggregate: Unknown aggregate 'intervalStdDev'. Allowed: count, sum, distinctCounterparties, ratio, rapidMovement, dormancyDays, profileRatio, peerRatio, newCustomers, customersPerDevice, cycle, newCountries, historyCount, historySum, historyRatio, distinctCount, reciprocalCount, consecutiveDays, newCounterpartyShare, sharedDeviceSenders, typeShareChange, minutesSinceEvent.. | L32: Claude (automated test suite) | M32: 2026-10-15 | N32: GAP-VEL-07 | O32: Automated: CapabilityGapTests.Scenario_not_configurable (rule validator evidence)
A33: TM-VEL-08-01 | B33: Velocity & Frequency | C33: VEL-08 | D33: High count of distinct channels in a day | E33: Positive | F33: C6 uses App, Agent, ATM and Web on same day totalling 1,500 | G33: Alert raised | H33: Low | I33: P3 | J33: Pass | K33: App, Agent, ATM and Web on one day totalling 1,500 → 1 alert (distinctCount of channel). | L33: Claude (automated test suite) | M33: 2026-10-15 | O33: Automated: ExtendedCapabilityTests.VEL_08_many_channels. Blocked in the first execution (capability gap); executable after the rule DSL extension.
A34: TM-VEL-08-02 | B34: Velocity & Frequency | C34: VEL-08 | D34: High count of distinct channels in a day | E34: Negative | F34: 4 channels but total 300 | G34: No alert | H34: Low | I34: P3 | J34: Pass | K34: 4 channels, total 300 → 0 alerts. | L34: Claude (automated test suite) | M34: 2026-10-15 | O34: Automated: ExtendedCapabilityTests.VEL_08_many_channels. Blocked in the first execution (capability gap); executable after the rule DSL extension.
A35: TM-VEL-08-03 | B35: Velocity & Frequency | C35: VEL-08 | D35: High count of distinct channels in a day | E35: Boundary | F35: 3 channels, 2,000 total | G35: No alert | H35: Low | I35: P3 | J35: Pass | K35: 3 channels, total 2,100 → 0 alerts. | L35: Claude (automated test suite) | M35: 2026-10-15 | O35: Automated: ExtendedCapabilityTests.VEL_08_many_channels. Blocked in the first execution (capability gap); executable after the rule DSL extension.
A36: TM-AMT-01-01 | B36: Amount & Thresholds | C36: AMT-01 | D36: Single large transaction | E36: Positive | F36: Individual C7 sends 10,000 JOD transfer | G36: Alert raised | H36: Medium | I36: P1 | J36: Pass | K36: Individual 10,000 JOD transfer → 1 alert. | L36: Claude (automated test suite) | M36: 2026-10-15 | O36: Automated: AmountTests.AMT_01_single_large_transaction
A37: TM-AMT-01-02 | B37: Amount & Thresholds | C37: AMT-01 | D37: Single large transaction | E37: Boundary | F37: 9,999.999 JOD | G37: No alert | H37: Medium | I37: P1 | J37: Pass | K37: 9,999.999 JOD → 0 alerts (decimal precision preserved). | L37: Claude (automated test suite) | M37: 2026-10-15 | O37: Automated: AmountTests.AMT_01_single_large_transaction
A38: TM-AMT-01-03 | B38: Amount & Thresholds | C38: AMT-01 | D38: Single large transaction | E38: Positive | F38: 15,000 USD equivalent ≥ threshold after FX conversion | G38: Alert raised; FX rate in evidence | H38: Medium | I38: P1 | J38: Pass | K38: 15,000 USD → base 10,635 JOD → 1 alert; FX rate 0.709 and date in evidence. | L38: Claude (automated test suite) | M38: 2026-10-15 | O38: Automated: AmountTests.AMT_01_single_large_transaction
A39: TM-AMT-01-04 | B39: Amount & Thresholds | C39: AMT-01 | D39: Single large transaction | E39: Negative | F39: Corporate sends 20,000 | G39: No alert (corporate threshold) | H39: Medium | I39: P1 | J39: Pass | K39: Corporate 20,000 (corporate threshold 50,000) → 0 alerts. | L39: Claude (automated test suite) | M39: 2026-10-15 | O39: Automated: AmountTests.AMT_01_single_large_transaction
A40: TM-AMT-01-05 | B40: Amount & Thresholds | C40: AMT-01 | D40: Single large transaction | E40: Edge | F40: Transaction Pending then Completed | G40: Alert only once, at configured status | H40: Medium | I40: P1 | J40: Pass | K40: While Pending: 0 alerts; after status update to Completed and two reruns: 1 alert (raised once, at configured status). | L40: Claude (automated test suite) | M40: 2026-10-15 | O40: Automated: AmountTests.AMT_01_single_large_transaction
...

Sheet Legend
A1: How to use | B1: Each scenario in 'Scenario Catalogue' is a configurable detection rule. 'Test Cases' prove it fires when it should (Positive), stays silent when it should (Negative), behaves correctly at the threshold (Boundary) and handles awkward data (Edge). Fill the shaded columns; Summary updates automatically.
A2: Example row | B2: TM-VEL-01-01 → Status: Pass · Actual Result: Alert ALR-000123 raised on 20th withdrawal, evidence lists 20 txns · Tester: QA1 · Execution Date: 2026-10-20
A3: Test types | B3: Positive = must alert. Negative = must not alert. Boundary = exactly at / just past the threshold. Edge = data or timing conditions (reversals, missing data, multiple wallets, time zones, VPN, late arrival).
A4: Parameters | B4: All thresholds (N, A, T, D, P...) are example defaults to make the tests concrete. Replace with values approved by compliance; boundary tests must be updated when a threshold changes.
A5: Amounts and time | B5: Amounts in JOD unless stated; other currencies are converted with the versioned FX rate. Calendar windows use local time (Asia/Amman); 'rolling' windows ignore calendar days.
A6: Counting rules | B6: Unless a test says otherwise: only Completed transactions count; aggregation is by resolved customer across all their wallets; fees and internal clearing legs are excluded; reversals follow each rule's netting policy.
A7: Expected result | B7: 'Alert raised' means one alert with severity as listed, the rule version, window boundaries and the matched transactions stored as evidence. Real-time scenarios (sanctions, sanctioned countries) also expect a Hold/Reject decision.
A8: Typology basis | B8: Scenarios follow red-flag typologies published by the FATF (e.g. guidance on money or value transfer services, prepaid cards/mobile/internet payments, terrorist financing and crowdfunding, virtual-asset red flags) and the Wolfsberg Group, adapted to an e-wallet/agent model.
A9: Test data | B9: Use fictitious customers (C1, C2...), wallets and test list entries only. Never use real customer data or real sanctions-list persons outside controlled test lists.
A10: Category codes | B10: VEL = Velocity & Frequency · AMT = Amount & Thresholds · STR = Structuring & Smurfing · RMV = Rapid Movement & Pass-through · FAN = Fan-in / Fan-out · GEO = Geographic & Impossible Travel · DEV = Device, IP & Channel · BEH = Behavioural Change & Profile Mismatch · CSH = Cash-in / Cash-out · AGT = Agent Network · MER = Merchant · REV = Reversals, Refunds & Failed Attempts · CIR = Circular & Related-party · MUL = Money Mule · XBR = Cross-border Remittance · PRP = Top-ups, Vouchers & Bill Payments · TF = Terrorist Financing Indicators · SAN = Sanctions & High-risk Counterparties · ATO = Account Takeover Overlap (FRAML) · VAG = Virtual Assets & Gambling · ENG = Engine Edge Cases (applies to all scenarios)

Sheet Defects & Gaps
A1: ID | B1: Type | C1: Description | D1: Affected test cases
A2: DEF-TM-01 | B2: Fixed and re-tested | C2: Own-wallet / self-transfer exclusion not configurable. Fix: Rule field txn.isOwnAccount | D2: TM-VEL-03-03
A3: DEF-TM-02 | B3: Fixed and re-tested | C3: Missing profile/attribute data silently evaluated as no-match. Fix: Missing inputs raise RuleInputMissing data-quality items (result incomplete) | D3: TM-AMT-03-04, TM-BEH-04-03
A4: DEF-TM-03 | B4: Fixed and re-tested | C4: Entity-resolution links not usable by rules or shown in evidence. Fix: Subject 'Entity' (linked customers, minimum confidence) and linkedParties in alert evidence | D4: TM-STR-03-04, TM-STR-04-03
A5: DEF-TM-04 | B5: Fixed and re-tested | C5: No secondary indicator flags / severity escalation. Fix: action.indicators (flag + optional severity) and counterparty.* fields | D5: TM-RMV-03-03, TM-FAN-01-04, TM-FAN-02-04
A6: DEF-TM-05 | B6: Fixed and re-tested | C6: Runs used the active rule version for all transactions. Fix: Manual runs evaluate each period with the version in force at transaction time | D6: TM-GEO-03-03
A7: DEF-TM-06 | B7: Fixed and re-tested | C7: No per-customer behavioural baseline. Fix: historyCount / historySum / historyRatio aggregates over the customer's own lookback | D7: TM-BEH-03-02
A8: DEF-TM-07 | B8: Fixed and re-tested | C8: Real-time list hits created no AML alert. Fix: Real-time list matches raise Critical/High alerts | D8: TM-SAN-01-01, TM-SAN-04-01
A9: DEF-TM-08 | B9: Fixed and re-tested | C9: Keyword matching without normalisation. Fix: contains normalises case, diacritics and letter spacing | D9: TM-SAN-02-03
A10: DEF-TM-09 | B10: Fixed and re-tested | C10: Later reversal not noted on the alert. Fix: LinkedTransactionReversed entry in alert history | D10: TM-ENG-02-03
A11: DEF-TM-10 | B11: Fixed and re-tested | C11: Late arrivals never re-evaluated / not logged. Fix: Scheduler re-evaluates late arrivals within Rules:LateArrivalLookbackDays; older ones raise LateArrivalNotEvaluated | D11: TM-ENG-06-01, TM-ENG-06-02
A12: DEF-TM-11 | B12: Fixed and re-tested | C12: No wallet-level aggregation; unresolved parties not evaluated. Fix: Subject 'Wallet' and unresolvedParties = Wallet | D12: TM-ENG-07-01, TM-ENG-07-02
... A41: GAP-XBR-03 | B41: Capability gap (test cases Blocked) | C41: Capability gap — No corridor share per peer group (nationality/segment). Closest rule definition rejected by the rule validator: $.condition.aggregate: Unknown aggregate 'corridorPeerShare'. Allowed: count, sum, distinctCounterparties, ratio, rapidMovement, dormancyDays, profileRatio, peerRatio, newCustomers, customersPerDevice, cycle, newCountries, historyCount, historySum, historyRatio, distinctCount, reciprocalCount, consecutiveDays, newCounterpartyShare, sharedDeviceSenders, typeShareChange, minutesSinceEvent.. | D41: TM-XBR-03-01, TM-XBR-03-02
